Workbook

Sheet data_extraction
A1: Serial | B1: Paper Title | C1: Year | D1: Domain 1: Bias due to confounding (Baseline fairness & experimental control) | I1: Domain 1 Overall Risk | J1: Domain 1 Risk | K1: Domain 1 Justification | L1: Domain 2: Bias in selection of datasets/workloads | Q1: Domain 2 Overall Risk | R1: Domain 2 Risk | S1: Domain 2 Justification | T1: Domain 3: Bias in implementation of methods | Y1: Domain 3 Overall Risk | Z1: Domain 3 Risk | AA1: Domain 3 Justification | AB1: Domain 4: Bias in experimental execution | AG1: Domain 4 Overall Risk | AH1: Domain 4 Risk | AI1: Domain 4 Justification | AJ1: Domain 5: Bias due to incomplete reporting | AO1: Domain 5 Overall Risk | AP1: Domain 5 Risk | AQ1: Domain 5 Justification | AR1: Domain 6: Bias in performance measurement | AW1: Domain 6 Overall Risk Score | AX1: Domain 6 Risk Assessment | AY1: Domain 6 Justification | AZ1: Domain 7: Bias in selective reporting | BE1: Domain 7 Overall Risk | BF1: Domain 7 Risk | BG1: Domain 7 Justification | BH1: Overall Risk Score | BI1: Overall Risk Assessment | BJ1: Exclude from Review?
D2: D1Q1: Were baseline methods clearly described and fairly implemented? | E2: D1Q2: Were experiments conducted on same hardware with controlled resources? | F2: D1Q3: Were confounding factors adequately controlled or reported? | G2: D1Q4: Were dataset characteristics adequately described? | H2: D1Q5: Were hyperparameters optimized fairly across all methods? | L2: D2Q1: Were dataset selection criteria clearly described? | M2: D2Q2: Do datasets cover diverse distributions? | N2: D2Q3: Were diverse string characteristics tested? | O2: D2Q4: Were both synthetic and real-world datasets included? | P2: D2Q5: Were datasets selected without evidence of cherry-picking? | T2: D3Q1: Is the learned index implementation clearly described? | U2: D3Q2: Is source code publicly available or reproducible? | V2: D3Q3: Are baseline implementations from reputable sources? | W2: D3Q4: Were model architectures and training procedures described? | X2: D3Q5: Does implementation match intended design? | AB2: D4Q1: Do reported experiments match methodology described? | AC2: D4Q2: Are insert/update/delete patterns clearly specified? | AD2: D4Q3: Are concurrency levels and thread interactions described? | AE2: D4Q4: Are failure scenarios realistic and recovery tested? | AF2: D4Q5: Were workload parameters clearly specified? | AJ2: D5Q1: Are all relevant metrics reported? | AK2: D5Q2: Are negative results or failure cases discussed? | AL2: D5Q3: Are limitations clearly acknowledged? | AM2: D5Q4: Are results reported for all tested configurations? | AN2: D5Q5: Are outliers or unexpected behaviors explained? | AR2: D6Q1: Are performance measurement methodologies clearly described? | AS2: D6Q2: Were multiple runs performed to account for variability? | AT2: D6Q3: Are confidence intervals or error bars reported? | AU2: D6Q4: Were warm-up periods used to eliminate cold-start effects? | AV2: D6Q5: Are measurement overheads accounted for? | AZ2: D7Q1: Are results reported for all datasets mentioned? | BA2: D7Q2: Are both favorable and unfavorable comparisons shown? | BB2: D7Q3: Were results reported without evidence of p-hacking or selective reporting? | BC2: D7Q4: Are reproducibility materials publicly available? | BD2: D7Q5: Were all promised experiments reported?
A3: 1 | B3: Learned Indexes with Distribution Smoothing via Virtual Points. | C3: 2025 | D3: 2 | E3: 2 | F3: 1 | G3: 2 | H3: 1 | I3: =SUM(D3:H3) -> 8 | J3: =IF(I3>=8,"Low",IF(I3>=4,"Moderate",IF(I3>=0,"Serious","Critical"))) -> Low | K3: The study demonstrates a high degree of experimental control by utilizing a standardized hardware environment and a recognized evaluation framework. Fairness is maintained by selecting widely recognized SOTA baselines and providing a transparent description of the datasets' difficulty and distributions. | L3: 2 | M3: 2 | N3: 0 | O3: 2 | P3: 2 | Q3: =SUM(L3:P3) -> 8 | R3: =IF(Q3>=8,"Low",IF(Q3>=4,"Moderate",IF(Q3>=0,"Serious","Critical"))) -> Low | S3: The research utilizes a comprehensive suite of real-world and synthetic datasets that represent varying levels of learning difficulty. The authors' transparency regarding the exclusion of certain benchmarks reinforces the validity of their methodology by defining the specific scenarios where the proposed CSV technique is most relevant. | T3: 2 | U3: 1 | V3: 2 | W3: 2 | X3: 2 | Y3: =SUM(T3:X3) -> 9 | Z3: =IF(Y3>=8,"Low",IF(Y3>=4,"Moderate",IF(Y3>=0,"Serious","Critical"))) -> Low | AA3: The paper includes a complexity analysis that aligns with the experimental results regarding pre-processing time and scalability. Additionally, it uses a cost model to ensure that structural modifications (like node merging) align with the design goal of balancing traversal and search time. | AB3: 2 | AC3: 2 | AD3: 1 | AE3: 0 | AF3: 2 | AG3: =SUM(AB3:AF3) -> 7 | AH3: =IF(AG3>=8,"Low",IF(AG3>=4,"Moderate",IF(AG3>=0,"Serious","Critical"))) -> Moderate | AI3: Workload parameters are explicitly detailed, including the use of 200 million keys per dataset, varying smoothing thresholds (α) from 0.05 to 0.8, and specific batch sizes for insertions. The distinction between "easy" and "hard" datasets provides clear context for interpreting different access patterns. | AJ3: 2 | AK3: 2 | AL3: 2 | AM3: 2 | AN3: 2 | AO3: =SUM(AJ3:AN3) -> 10 | AP3: =IF(AO3>=8,"Low",IF(AO3>=4,"Moderate",IF(AO3>=0,"Serious","Critical"))) -> Low | AQ3: The authors explain fluctuations in ALEX results as a byproduct of its runtime cost model. They also provide a clear explanation for performance drops in the OSM dataset during insertions, linking them to specific structural properties of the original index. | AR3: 1 | AS3: 2 | AT3: 0 | AU3: 0 | AV3: 0 | AW3: =sum(AR3:AV3) -> 3 | AX3: =IF(AW3>=8,"Low",IF(AW3>=4,"Moderate",IF(AW3>=0,"Serious","Critical"))) -> Serious | AY3: While the experimental setup is documented and utilizes 25 repeated runs per query to ensure stable averages, the sources lack critical statistical details such as variance, error bars, or confidence intervals. Additionally, there is no explicit mention of warm-up phases or the mitigation of measurement overhead within the provided technical excerpts. | AZ3: 1 | BA3: 2 | BB3: 2 | BC3: 1 | BD3: 2 | BE3: =sum(AZ3:BD3) -> 8 | BF3: =IF(BE3>=8,"Low",IF(BE3>=4,"Moderate",IF(BE3>=0,"Serious","Critical"))) -> Low | BG3: The study avoids "cherry-picking" by reporting that the CSV method primarily benefits "promoted data" while leaving average performance for random data largely unchanged compared to the original indexes. Although certain datasets were omitted for ALEX because they were too simple for the smoothing technique to be relevant, the overall results follow a consistent and logically explained framework. | BH3: =SUM(I3,Q3,Y3,AG3,AO3,AW3,BE3) -> 53 | BI3: =IF(BH3>=56,"Low",IF(BH3>=35,"Moderate",IF(BH3>=14,"Serious","Critical"))) -> Moderate | BJ3: FALSE
A4: 2 | B4: Kanva: A Lock-free Learned Search Data Structure | C4: 2024 | D4: 2 | E4: 2 | F4: 2 | G4: 2 | H4: 1 | I4: =SUM(D4:H4) -> 9 | J4: =IF(I4>=8,"Low",IF(I4>=4,"Moderate",IF(I4>=0,"Serious","Critical"))) -> Low | K4: The study maintains a high level of experimental control by using a standardized hardware platform and a modern compiler environment for all compared methods. By including a "warm-up" period and accounting for memory reclamation overhead, the authors ensure that the comparisons are grounded in realistic system behaviors. | L4: 2 | M4: 2 | N4: 0 | O4: 2 | P4: 2 | Q4: =SUM(L4:P4) -> 8 | R4: =IF(Q4>=8,"Low",IF(Q4>=4,"Moderate",IF(Q4>=0,"Serious","Critical"))) -> Low | S4: The paper utilizes a robust suite of datasets that reflects both theoretical distributions and practical, real-world data patterns. The inclusion of skewed Zipfian distributions and varied hotspot ratios demonstrates a commitment to testing the data structure under challenging, high-contention conditions. | T4: 2 | U4: 2 | V4: 2 | W4: 2 | X4: 2 | Y4: =SUM(T4:X4) -> 10 | Z4: =IF(Y4>=8,"Low",IF(Y4>=4,"Moderate",IF(Y4>=0,"Serious","Critical"))) -> Low | AA4: The implementation of Kanva is thoroughly documented through both architectural diagrams and pseudocode for all core operations. By providing a public GitHub repository and detailed evaluations of different internal fitting schemes, the authors ensure the methodology is transparent and reproducible. | AB4: 2 | AC4: 2 | AD4: 2 | AE4: 0 | AF4: 2 | AG4: =SUM(AB4:AF4) -> 8 | AH4: =IF(AG4>=8,"Low",IF(AG4>=4,"Moderate",IF(AG4>=0,"Serious","Critical"))) -> Low | AI4: Experimental execution follows a rigorous protocol using standardized benchmarks and a high-performance multi-core hardware environment. The use of various thread counts and clearly defined read/write ratios provides a comprehensive view of how the data structure handles high-contention scenarios. | AJ4: 2 | AK4: 2 | AL4: 2 | AM4: 2 | AN4: 2 | AO4: =SUM(AJ4:AN4) -> 10 | AP4: =IF(AO4>=8,"Low",IF(AO4>=4,"Moderate",IF(AO4>=0,"Serious","Critical"))) -> Low | AQ4: The researchers provide a transparent evaluation that includes peak memory usage and build times alongside standard throughput metrics. They do not shy away from reporting adverse results, such as performance degradation under high skew, and provide detailed technical reasons for these behaviors. | AR4: 1 | AS4: 1 | AT4: -1 | AU4: 2 | AV4: 1 | AW4: =sum(AR4:AV4) -> 4 | AX4: =IF(AW4>=8,"Low",IF(AW4>=4,"Moderate",IF(AW4>=0,"Serious","Critical"))) -> Moderate | AY4: The study follows good practices by utilizing a warm-up phase to eliminate cold-start bias and provides a very detailed description of the hardware platform. However, the omission of error bars in the charts and specific iteration counts makes it harder to assess the precise statistical variance of the results. | AZ4: 2 | BA4: 2 | BB4: 2 | BC4: 2 | BD4: 2 | BE4: =sum(AZ4:BD4) -> 10 | BF4: =IF(BE4>=8,"Low",IF(BE4>=4,"Moderate",IF(BE4>=0,"Serious","Critical"))) -> Low | BG4: The paper exhibits high transparency by providing the source code and using standard, publicly available benchmarks for all evaluations. The reporting is balanced, showing both the strengths of the lock-free learned approach and the scenarios where traditional synchronization methods remain competitive. | BH4: =SUM(I4,Q4,Y4,AG4,AO4,AW4,BE4) -> 59 | BI4: =IF(BH4>=56,"Low",IF(BH4>=35,"Moderate",IF(BH4>=14,"Serious","Critical"))) -> Low | BJ4: FALSE
A5: 3 | B5: TONE: cutting tail-latency in learned indexes | D5: 2 | E5: 2 | F5: 0 | G5: 2 | H5: 2 | I5: =SUM(D5:H5) -> 8 | J5: =IF(I5>=8,"Low",IF(I5>=4,"Moderate",IF(I5>=0,"Serious","Critical"))) -> Low | K5: The study maintains strong experimental control by utilizing a consistent hardware environment and applying standard industry configurations to the baseline indexes. However, it lacks detailed reporting on low-level system controls like cache management or specific compiler optimizations. | L5: 2 | M5: 2 | N5: 0 | O5: 1 | P5: 2 | Q5: =SUM(L5:P5) -> 7 | R5: =IF(Q5>=8,"Low",IF(Q5>=4,"Moderate",IF(Q5>=0,"Serious","Critical"))) -> Moderate | S5: The research effectively uses a mix of standardized and trace-inspired synthetic workloads to stress-test the index. By reporting results even in scenarios where the proposed method does not offer a significant advantage over existing learned indexes, the authors minimize selection bias. | T5: 2 | U5: 2 | V5: 2 | W5: 2 | X5: 2 | Y5: =SUM(T5:X5) -> 10 | Z5: =IF(Y5>=8,"Low",IF(Y5>=4,"Moderate",IF(Y5>=0,"Serious","Critical"))) -> Low | AA5: The implementation reporting is transparent and highly reproducible, supported by both pseudocode and an open-source repository. The use of official repositories for all baseline comparisons further ensures that the performance gains reported are due to architectural improvements rather than implementation disparities. | AB5: 2 | AC5: 2 | AD5: 2 | AE5: 0 | AF5: 2 | AG5: =SUM(AB5:AF5) -> 8 | AH5: =IF(AG5>=8,"Low",IF(AG5>=4,"Moderate",IF(AG5>=0,"Serious","Critical"))) -> Low | AI5: The study follows a highly structured execution plan, utilizing industry-standard benchmarks alongside custom traces modeled after real-world production data. Concurrency is well-documented through a sharding approach, and all operational parameters are transparently reported. | AJ5: 1 | AK5: 2 | AL5: 2 | AM5: 2 | AN5: 2 | AO5: =SUM(AJ5:AN5) -> 9 | AP5: =IF(AO5>=8,"Low",IF(AO5>=4,"Moderate",IF(AO5>=0,"Serious","Critical"))) -> Low | AQ5: The reporting is transparent and includes honest assessments of where the system does not outperform its predecessors. By explaining the technical reasons behind performance fluctuations in both their system and the baselines, the authors provide a balanced view of the results. | AR5: 1 | AS5: 2 | AT5: 1 | AU5: 0 | AV5: 0 | AW5: =sum(AR5:AV5) -> 4 | AX5: =IF(AW5>=8,"Low",IF(AW5>=4,"Moderate",IF(AW5>=0,"Serious","Critical"))) -> Moderate | AY5: The measurement process is sound in its use of multiple experimental runs and high-percentile latency reporting. However, the lack of detail regarding cache warming and measurement overhead leaves some minor uncertainty regarding low-level performance precision. | AZ5: 2 | BA5: 2 | BB5: 2 | BC5: 2 | BD5: 2 | BE5: =sum(AZ5:BD5) -> 10 | BF5: =IF(BE5>=8,"Low",IF(BE5>=4,"Moderate",IF(BE5>=0,"Serious","Critical"))) -> Low | BG5: The paper demonstrates high integrity in its reporting by including a full suite of standard benchmarks and providing public access to the source code. The inclusion of results where TONE does not provide a benefit over existing methods further reinforces the objectivity of the study. | BH5: =SUM(I5,Q5,Y5,AG5,AO5,AW5,BE5) -> 56 | BI5: =IF(BH5>=56,"Low",IF(BH5>=35,"Moderate",IF(BH5>=14,"Serious","Critical"))) -> Low | BJ5: FALSE
A6: 4 | B6: Limousine: Blending learned and classical indexes to self-design larger-than-memory cloud storage engines | C6: 2024 | D6: 2 | E6: 2 | F6: 1 | G6: 2 | H6: 2 | I6: =SUM(D6:H6) -> 9 | J6: =IF(I6>=8,"Low",IF(I6>=4,"Moderate",IF(I6>=0,"Serious","Critical"))) -> Low | K6: The authors maintain high experimental rigour by using a wide array of both classical and learned baselines and providing transparent hardware and cloud VM specifications. Confounding factors like memory residency are explicitly modeled to ensure the accuracy of performance estimations. | L6: 2 | M6: 2 | N6: 0 | O6: 2 | P6: 2 | Q6: =SUM(L6:P6) -> 8 | R6: =IF(Q6>=8,"Low",IF(Q6>=4,"Moderate",IF(Q6>=0,"Serious","Critical"))) -> Low | S6: The research utilizes a comprehensive suite of datasets and workloads that represent both theoretical distributions and real-world applications. By testing across all standard YCSB variants, the authors ensure the system is evaluated against diverse and challenging operational requirements. | T6: 2 | U6: 1 | V6: 2 | W6: 2 | X6: 2 | Y6: =SUM(T6:X6) -> 9 | Z6: =IF(Y6>=8,"Low",IF(Y6>=4,"Moderate",IF(Y6>=0,"Serious","Critical"))) -> Low | AA6: The implementation is described with exceptional technical depth, moving from abstract design principles to specific Rust-based code generation techniques. The use of established industrial baselines and a rigorous multi-step validation process ensures that the system's performance is measured against fair and representative targets. | AB6: 2 | AC6: 2 | AD6: 2 | AE6: 0 | AF6: 2 | AG6: =SUM(AB6:AF6) -> 8 | AH6: =IF(AG6>=8,"Low",IF(AG6>=4,"Moderate",IF(AG6>=0,"Serious","Critical"))) -> Low | AI6: The experimental execution is highly transparent, utilizing standardized benchmarks (YCSB) and detailed cloud environment specifications. While the paper excels in performance and concurrency modeling, the provided excerpts lack specific details on crash-consistency testing, though the fundamental mechanism for disk persistence is noted. | AJ6: 2 | AK6: 2 | AL6: 2 | AM6: 2 | AN6: 2 | AO6: =SUM(AJ6:AN6) -> 10 | AP6: =IF(AO6>=8,"Low",IF(AO6>=4,"Moderate",IF(AO6>=0,"Serious","Critical"))) -> Low | AQ6: The paper provides a transparent and holistic reporting of performance, openly discussing the inherent weaknesses of learned structures and the limitations of their own search algorithms. By explaining variances in cloud-based measurements, the authors ensure the results are contextualized rather than presented as perfect. | AR6: 1 | AS6: 2 | AT6: 2 | AU6: 0 | AV6: 1 | AW6: =sum(AR6:AV6) -> 6 | AX6: =IF(AW6>=8,"Low",IF(AW6>=4,"Moderate",IF(AW6>=0,"Serious","Critical"))) -> Moderate | AY6: The use of error bars and large-scale query counts (30M) demonstrates a commitment to statistical reliability. While some low-level details like warm-up periods are missing from the text, the overall measurement framework is robust and accounts for the inherent variability of cloud environments. | AZ6: 2 | BA6: 2 | BB6: 2 | BC6: 1 | BD6: 2 | BE6: =sum(AZ6:BD6) -> 9 | BF6: =IF(BE6>=8,"Low",IF(BE6>=4,"Moderate",IF(BE6>=0,"Serious","Critical"))) -> Low | BG6: The paper adheres strictly to its stated methodology, reporting results across a diverse and standardized set of benchmarks and datasets. The inclusion of "unfavorable" data points—such as model accuracy drops or performance convergence with baselines—reinforces the objectivity of the reporting. | BH6: =SUM(I6,Q6,Y6,AG6,AO6,AW6,BE6) -> 59 | BI6: =IF(BH6>=56,"Low",IF(BH6>=35,"Moderate",IF(BH6>=14,"Serious","Critical"))) -> Low | BJ6: FALSE
A7: 5 | B7: Updatable learned index with precise positions | D7: 2 | E7: 2 | F7: 1 | G7: 2 | H7: 2 | I7: =SUM(D7:H7) -> 9 | J7: =IF(I7>=8,"Low",IF(I7>=4,"Moderate",IF(I7>=0,"Serious","Critical"))) -> Low | K7: The researchers provide a transparent experimental setup with detailed hardware and compiler specifications. They ensure a fair baseline comparison by using standard implementations and conducting a comprehensive parameter analysis to justify their chosen configurations. | L7: 2 | M7: 2 | N7: 0 | O7: 2 | P7: 2 | Q7: =SUM(L7:P7) -> 8 | R7: =IF(Q7>=8,"Low",IF(Q7>=4,"Moderate",IF(Q7>=0,"Serious","Critical"))) -> Low | S7: LIPP is evaluated against a robust variety of datasets that include both real-world and synthetic distributions. The inclusion of diverse workloads with varying read/write ratios ensures that the performance gains reported are not limited to specific, favorable conditions. | T7: 2 | U7: 2 | V7: 2 | W7: 2 | X7: 2 | Y7: =SUM(T7:X7) -> 10 | Z7: =IF(Y7>=8,"Low",IF(Y7>=4,"Moderate",IF(Y7>=0,"Serious","Critical"))) -> Low | AA7: The implementation of LIPP is meticulously documented with pseudocode and algorithmic proofs, ensuring that the precise-position mechanism is understandable and reproducible. The availability of source code and the use of optimized, reputable baselines further minimize the risk of implementation bias. | AB7: 2 | AC7: 2 | AD7: 0 | AE7: 0 | AF7: 2 | AG7: =SUM(AB7:AF7) -> 6 | AH7: =IF(AG7>=8,"Low",IF(AG7>=4,"Moderate",IF(AG7>=0,"Serious","Critical"))) -> Moderate | AI7: The experimental execution follows a rigorous methodology that aligns perfectly with the reported results across diverse datasets and dynamic workloads. While concurrency and crash consistency are not evaluated, this is consistent with the paper's stated scope of being a single-threaded in-memory index evaluation. | AJ7: 2 | AK7: 2 | AL7: 1 | AM7: 2 | AN7: 2 | AO7: =SUM(AJ7:AN7) -> 9 | AP7: =IF(AO7>=8,"Low",IF(AO7>=4,"Moderate",IF(AO7>=0,"Serious","Critical"))) -> Low | AQ7: The paper is highly transparent, providing a multi-dimensional performance analysis that includes throughput, memory, and latency metrics. It explicitly discusses scenarios where the proposed method faces challenges, such as highly non-uniform data distributions. | AR7: 1 | AS7: 2 | AT7: 2 | AU7: 0 | AV7: 0 | AW7: =sum(AR7:AV7) -> 5 | AX7: =IF(AW7>=8,"Low",IF(AW7>=4,"Moderate",IF(AW7>=0,"Serious","Critical"))) -> Moderate | AY7: The researchers followed good practice by performing multiple experimental runs and reporting variance through standard deviation and 99th percentile metrics. However, details regarding warm-up periods and measurement overhead quantification are missing from the provided text. | AZ7: 2 | BA7: 2 | BB7: 2 | BC7: 2 | BD7: 2 | BE7: =sum(AZ7:BD7) -> 10 | BF7: =IF(BE7>=8,"Low",IF(BE7>=4,"Moderate",IF(BE7>=0,"Serious","Critical"))) -> Low | BG7: The paper adheres to high standards of scientific reporting by making artifacts publicly available for reproducibility. It presents a balanced view by showing that performance gains vary significantly depending on the dataset's uniformity and the specific operation being performed. | BH7: =SUM(I7,Q7,Y7,AG7,AO7,AW7,BE7) -> 57 | BI7: =IF(BH7>=56,"Low",IF(BH7>=35,"Moderate",IF(BH7>=14,"Serious","Critical"))) -> Low | BJ7: FALSE
A8: 6 | B8: HL-LSM: A LSM-Tree Combined with Read Hotness and Learned Index | C8: 2024 | D8: 2 | E8: 2 | F8: 1 | G8: 2 | H8: 1 | I8: =SUM(D8:H8) -> 8 | J8: =IF(I8>=8,"Low",IF(I8>=4,"Moderate",IF(I8>=0,"Serious","Critical"))) -> Low | K8: The research provides a transparent baseline and specific hardware environment details, ensuring a fair physical setup for the experiments. It effectively describes the data types and workload volumes, though it lacks deep detail on the specific tuning of legacy baseline configurations. | L8: 1 | M8: 1 | N8: 0 | O8: 0 | P8: 2 | Q8: =SUM(L8:P8) -> 4 | R8: =IF(Q8>=8,"Low",IF(Q8>=4,"Moderate",IF(Q8>=0,"Serious","Critical"))) -> Moderate | S8: The researchers demonstrate a transparent evaluation by showing the system's limitations in low-read scenarios. While the workloads cover essential patterns (hot vs. random), the assessment is limited by the exclusive use of synthetic data and a lack of real-world traces. | T8: 2 | U8: 0 | V8: 2 | W8: 2 | X8: 2 | Y8: =SUM(T8:X8) -> 8 | Z8: =IF(Y8>=8,"Low",IF(Y8>=4,"Moderate",IF(Y8>=0,"Serious","Critical"))) -> Low | AA8: The algorithmic description and architectural logic are highly detailed, providing a clear map of how the prefix search and interpolation points function. The use of reputable baselines strengthens the implementation's credibility, though the lack of public source code limits immediate reproducibility. | AB8: 2 | AC8: 1 | AD8: 1 | AE8: 0 | AF8: 2 | AG8: =SUM(AB8:AF8) -> 6 | AH8: =IF(AG8>=8,"Low",IF(AG8>=4,"Moderate",IF(AG8>=0,"Serious","Critical"))) -> Moderate | AI8: The experimental execution closely follows the architectural design, particularly in how it validates the background construction of indexes and the distribution of hot keys. While specific details on write patterns and general thread counts are thin, the core workload parameters are well-defined. | AJ8: 1 | AK8: 2 | AL8: 2 | AM8: 2 | AN8: 2 | AO8: =SUM(AJ8:AN8) -> 9 | AP8: =IF(AO8>=8,"Low",IF(AO8>=4,"Moderate",IF(AO8>=0,"Serious","Critical"))) -> Low | AQ8: The reporting is highly transparent, notably including instances where the proposed system performs worse than the baselines. The primary missing element is a quantitative measurement of the memory overhead for the learned index. | AR8: 1 | AS8: 0 | AT8: -1 | AU8: 0 | AV8: 1 | AW8: =sum(AR8:AV8) -> 1 | AX8: =IF(AW8>=8,"Low",IF(AW8>=4,"Moderate",IF(AW8>=0,"Serious","Critical"))) -> Serious | AY8: While the results demonstrate clear trends, the paper lacks statistical rigor. The absence of error bars and details regarding multiple experimental trials makes it difficult to assess the stability of the reported performance gains. | AZ8: 2 | BA8: 2 | BB8: 2 | BC8: 0 | BD8: 2 | BE8: =sum(AZ8:BD8) -> 8 | BF8: =IF(BE8>=8,"Low",IF(BE8>=4,"Moderate",IF(BE8>=0,"Serious","Critical"))) -> Low | BG8: The authors demonstrate a high level of integrity by presenting a balanced view of the system’s performance, including its weaknesses. However, the lack of accessible source code remains a barrier to full independent verification. | BH8: =SUM(I8,Q8,Y8,AG8,AO8,AW8,BE8) -> 44 | BI8: =IF(BH8>=56,"Low",IF(BH8>=35,"Moderate",IF(BH8>=14,"Serious","Critical"))) -> Moderate | BJ8: FALSE
A9: 7 | B9: From LeanStore to LearnedStore: Using a Learned Index to Improve Database Index Search | C9: 2023 (Specifically December 2023) | D9: 2 | E9: 2 | F9: 2 | G9: 2 | H9: 1 | I9: =SUM(D9:H9) -> 9 | J9: =IF(I9>=8,"Low",IF(I9>=4,"Moderate",IF(I9>=0,"Serious","Critical"))) -> Low | K9: The paper demonstrates high experimental rigor by using a high-performance baseline and controlling for hardware-level confounding factors like NUMA effects. The documentation of dataset characteristics is comprehensive, though more detail on baseline hyperparameter tuning would be beneficial. | L9: 2 | M9: 2 | N9: 0 | O9: 2 | P9: 2 | Q9: =SUM(L9:P9) -> 8 | R9: =IF(Q9>=8,"Low",IF(Q9>=4,"Moderate",IF(Q9>=0,"Serious","Critical"))) -> Low | S9: The paper utilizes a robust and diverse set of workloads that successfully challenge the index across different storage tiers (RAM vs. SSD). The inclusion of standard benchmarks like SOSD and YCSB adds further credibility to the selection process. | T9: 2 | U9: 0 | V9: 2 | W9: 2 | X9: 2 | Y9: =SUM(T9:X9) -> 8 | Z9: =IF(Y9>=8,"Low",IF(Y9>=4,"Moderate",IF(Y9>=0,"Serious","Critical"))) -> Low | AA9: The methodology is mathematically and architecturally sound, with a clear explanation of how the learned model integrates with the existing B+-tree structure. While the description is highly reproducible in theory, the lack of a public code repository is a notable gap in evidence for this domain. | AB9: 2 | AC9: 2 | AD9: 1 | AE9: 0 | AF9: 2 | AG9: =SUM(AB9:AF9) -> 7 | AH9: =IF(AG9>=8,"Low",IF(AG9>=4,"Moderate",IF(AG9>=0,"Serious","Critical"))) -> Moderate | AI9: The experimental execution is highly consistent with the described hybrid architecture and covers a diverse range of operational mixes (read vs. write). However, the paper lacks depth regarding the internal concurrency management of the learned index models and does not address crash consistency. | AJ9: 2 | AK9: 2 | AL9: 2 | AM9: 2 | AN9: 2 | AO9: =SUM(AJ9:AN9) -> 10 | AP9: =IF(AO9>=8,"Low",IF(AO9>=4,"Moderate",IF(AO9>=0,"Serious","Critical"))) -> Low | AQ9: Reporting is comprehensive and remarkably transparent regarding the weaknesses of learned indexes. The inclusion of tail latency and startup time metrics provides a more complete picture of system performance than throughput alone. | AR9: 1 | AS9: 1 | AT9: -1 | AU9: 2 | AV9: 1 | AW9: =sum(AR9:AV9) -> 4 | AX9: =IF(AW9>=8,"Low",IF(AW9>=4,"Moderate",IF(AW9>=0,"Serious","Critical"))) -> Moderate | AY9: The study is strong in its handling of system states (warm vs. cold), which is often a major source of bias in database research. The primary weakness is the lack of statistical variance reporting (error bars) on the throughput aggregates. | AZ9: 2 | BA9: 2 | BB9: 2 | BC9: 1 | BD9: 2 | BE9: =sum(AZ9:BD9) -> 9 | BF9: =IF(BE9>=8,"Low",IF(BE9>=4,"Moderate",IF(BE9>=0,"Serious","Critical"))) -> Low | BG9: The paper maintains high integrity by showing a wide range of results, including cases where the proposed system is less effective. The reliance on established benchmarks like SOSD further bolsters the reliability of the reported results. | BH9: =SUM(I9,Q9,Y9,AG9,AO9,AW9,BE9) -> 55 | BI9: =IF(BH9>=56,"Low",IF(BH9>=35,"Moderate",IF(BH9>=14,"Serious","Critical"))) -> Moderate | BJ9: FALSE
A10: 8 | B10: Learned index for non-key queries | D10: 1 | E10: 2 | F10: 0 | G10: 2 | H10: 0 | I10: =SUM(D10:H10) -> 5 | J10: =IF(I10>=8,"Low",IF(I10>=4,"Moderate",IF(I10>=0,"Serious","Critical"))) -> Moderate | K10: The paper provides excellent transparency regarding hardware specifications and dataset variety, ensuring the environmental context is clear. However, there is a lack of detail regarding environmental controls like cache management and the specific optimization rigor applied to the baseline reimplementations. | L10: 1 | M10: 2 | N10: 0 | O10: 2 | P10: 2 | Q10: =SUM(L10:P10) -> 7 | R10: =IF(Q10>=8,"Low",IF(Q10>=4,"Moderate",IF(Q10>=0,"Serious","Critical"))) -> Moderate | S10: The researchers utilized a robust mix of synthetic and real-world data to validate their claims across various mathematical distributions. The inclusion of varying non-key proportions ensures the performance claims are tested against diverse query workloads rather than just ideal scenarios. | T10: 2 | U10: 0 | V10: 1 | W10: 2 | X10: 2 | Y10: =SUM(T10:X10) -> 7 | Z10: =IF(Y10>=8,"Low",IF(Y10>=4,"Moderate",IF(Y10>=0,"Serious","Critical"))) -> Moderate | AA10: The implementation is documented thoroughly through pseudocode and structural definitions, allowing for a clear understanding of the HBFdex logic. However, the reliance on internal reimplementations for baselines and the lack of a public code link prevents a higher score for reproducibility. | AB10: 2 | AC10: 2 | AD10: 0 | AE10: 0 | AF10: 2 | AG10: =SUM(AB10:AF10) -> 6 | AH10: =IF(AG10>=8,"Low",IF(AG10>=4,"Moderate",IF(AG10>=0,"Serious","Critical"))) -> Moderate | AI10: The experimental execution aligns perfectly with the described algorithms and includes detailed workload ratios for dynamic operations. While concurrency and failure recovery are not addressed, they are outside the stated scope of the single-threaded performance evaluation. | AJ10: 2 | AK10: 2 | AL10: 2 | AM10: 2 | AN10: 2 | AO10: =SUM(AJ10:AN10) -> 10 | AP10: =IF(AO10>=8,"Low",IF(AO10>=4,"Moderate",IF(AO10>=0,"Serious","Critical"))) -> Low | AQ10: The reporting is highly transparent, covering a wide array of performance dimensions. Crucially, the authors do not hide the index's limitations regarding positive-only query workloads or the inherent complexities of deleting data from Bloom filters. | AR10: 0 | AS10: 0 | AT10: -1 | AU10: 0 | AV10: 0 | AW10: =sum(AR10:AV10) -> -1 | AX10: =IF(AW10>=8,"Low",IF(AW10>=4,"Moderate",IF(AW10>=0,"Serious","Critical"))) -> Critical | AY10: While the high-level environment is documented, the paper lacks the technical depth required to assess the precision of its measurements. The absence of error bars and the lack of clarity on experimental repetitions or warm-up procedures represent a moderate risk of measurement bias. | AZ10: 2 | BA10: 2 | BB10: 2 | BC10: 1 | BD10: 2 | BE10: =sum(AZ10:BD10) -> 9 | BF10: =IF(BE10>=8,"Low",IF(BE10>=4,"Moderate",IF(BE10>=0,"Serious","Critical"))) -> Low | BG10: The paper demonstrates strong integrity in reporting, showing a balanced view of performance across various scales and distributions. While the underlying datasets are accessible to the public, the lack of released source code limits full independent reproducibility. | BH10: =SUM(I10,Q10,Y10,AG10,AO10,AW10,BE10) -> 43 | BI10: =IF(BH10>=56,"Low",IF(BH10>=35,"Moderate",IF(BH10>=14,"Serious","Critical"))) -> Moderate | BJ10: FALSE
A11: 9 | B11: {HiDPU}: A {DPU-Oriented} Hybrid Indexing Scheme for Disaggregated Storage Systems | D11: 2 | E11: 2 | F11: 1 | G11: 2 | H11: 2 | I11: =SUM(D11:H11) -> 9 | J11: =IF(I11>=8,"Low",IF(I11>=4,"Moderate",IF(I11>=0,"Serious","Critical"))) -> Low | K11: The researchers maintained high experimental control by using identical hardware for all tests and clearly defining the architectural differences between HiDPU and its baselines. By providing a sensitivity analysis and detailed dataset characteristics, they demonstrate a commitment to fair performance evaluation across different workloads. | L11: 2 | M11: 2 | N11: 0 | O11: 2 | P11: 2 | Q11: =SUM(L11:P11) -> 8 | R11: =IF(Q11>=8,"Low",IF(Q11>=4,"Moderate",IF(Q11>=0,"Serious","Critical"))) -> Low | S11: The researchers utilized a broad spectrum of standardized traces and benchmarks that represent various data center scenarios. Their inclusion of workloads that specifically challenge their proposed Pilot Cache (such as random OLTP patterns) suggests a balanced and non-biased selection of experimental data. | T11: 2 | U11: 2 | V11: 2 | W11: 2 | X11: 2 | Y11: =SUM(T11:X11) -> 10 | Z11: =IF(Y11>=8,"Low",IF(Y11>=4,"Moderate",IF(Y11>=0,"Serious","Critical"))) -> Low | AA11: The methodology is transparent, with a publicly available artifact and thorough descriptions of both the proposed system and its optimized baselines. The use of a breakdown analysis provides clear evidence that the implementation functions according to the intended design principles. | AB11: 2 | AC11: 2 | AD11: 2 | AE11: 1 | AF11: 2 | AG11: =SUM(AB11:AF11) -> 9 | AH11: =IF(AG11>=8,"Low",IF(AG11>=4,"Moderate",IF(AG11>=0,"Serious","Critical"))) -> Low | AI11: The researchers provide a detailed account of how the system handles concurrent operations and dynamic updates, matching these descriptions with experimental results that scale up to 256 clients. While formal crash-consistency testing is not the primary focus, the mechanisms for maintaining index consistency during updates are well-documented. | AJ11: 2 | AK11: 2 | AL11: 1 | AM11: 2 | AN11: 2 | AO11: =SUM(AJ11:AN11) -> 9 | AP11: =IF(AO11>=8,"Low",IF(AO11>=4,"Moderate",IF(AO11>=0,"Serious","Critical"))) -> Low | AQ11: The study is comprehensive, reporting multiple performance dimensions and explicitly discussing scenarios where the proposed system—or its baselines—face performance degradation. The inclusion of reconstruction overhead analysis provides a complete picture of the system's operational lifecycle. | AR11: 1 | AS11: 1 | AT11: 0 | AU11: 0 | AV11: 1 | AW11: =sum(AR11:AV11) -> 3 | AX11: =IF(AW11>=8,"Low",IF(AW11>=4,"Moderate",IF(AW11>=0,"Serious","Critical"))) -> Serious | AY11: While the metrics are standard for the field, the absence of error bars and explicit mention of warm-up periods represents a minor reporting gap. However, the use of detailed latency breakdowns and large query batches suggests a rigorous approach to quantifying system behavior. | AZ11: 2 | BA11: 2 | BB11: 2 | BC11: 2 | BD11: 2 | BE11: =sum(AZ11:BD11) -> 10 | BF11: =IF(BE11>=8,"Low",IF(BE11>=4,"Moderate",IF(BE11>=0,"Serious","Critical"))) -> Low | BG11: The paper demonstrates a high level of transparency by providing a public artifact, reporting results for all mentioned datasets, and including a sensitivity analysis. The balanced presentation of results across varied workloads suggests a lack of selective reporting. | BH11: =SUM(I11,Q11,Y11,AG11,AO11,AW11,BE11) -> 58 | BI11: =IF(BH11>=56,"Low",IF(BH11>=35,"Moderate",IF(BH11>=14,"Serious","Critical"))) -> Low | BJ11: FALSE
A12: 10 | B12: Towards Optimizing Learned Index for High Performance, Memory Efficiency and NUMA Awareness | C12: 2025 | D12: 2 | E12: 2 | F12: 2 | G12: 1 | H12: 2 | I12: =SUM(D12:H12) -> 9 | J12: =IF(I12>=8,"Low",IF(I12>=4,"Moderate",IF(I12>=0,"Serious","Critical"))) -> Low | K12: The study provides a high level of transparency regarding its hardware environment and the specific configurations of baseline models, ensuring that comparisons are made on an even playing field. By implementing a warm-up period and matching node sizes across different index types, the authors minimize potential performance artifacts. | L12: 1 | M12: 2 | N12: 0 | O12: 2 | P12: 2 | Q12: =SUM(L12:P12) -> 7 | R12: =IF(Q12>=8,"Low",IF(Q12>=4,"Moderate",IF(Q12>=0,"Serious","Critical"))) -> Moderate | S12: The study provides a high level of transparency regarding its hardware environment and the specific configurations of baseline models, ensuring that comparisons are made on an even playing field. By implementing a warm-up period and matching node sizes across different index types, the authors minimize potential performance artifacts. | T12: 2 | U12: 1 | V12: 2 | W12: 2 | X12: 2 | Y12: =SUM(T12:X12) -> 9 | Z12: =IF(Y12>=8,"Low",IF(Y12>=4,"Moderate",IF(Y12>=0,"Serious","Critical"))) -> Low | AA12: The implementation is described with a high degree of technical granularity, covering the mathematical scaling of models and the logic behind phase-based data migration. The use of established benchmarks and thorough sensitivity testing ensures that the reported system functions as the theoretical design intended. | AB12: 2 | AC12: 2 | AD12: 2 | AE12: 1 | AF12: 2 | AG12: =SUM(AB12:AF12) -> 9 | AH12: =IF(AG12>=8,"Low",IF(AG12>=4,"Moderate",IF(AG12>=0,"Serious","Critical"))) -> Low | AI12: The experimental execution is robust, utilizing industry-standard benchmarks (YCSB) and varied real-world datasets to test the system under stress. The clear specification of thread counts and the use of realistic data skew provide a high level of confidence in the experimental results, though more direct testing of crash recovery speed would further strengthen the persistence claims. | AJ12: 2 | AK12: 2 | AL12: 2 | AM12: 2 | AN12: 2 | AO12: =SUM(AJ12:AN12) -> 10 | AP12: =IF(AO12>=8,"Low",IF(AO12>=4,"Moderate",IF(AO12>=0,"Serious","Critical"))) -> Low | AQ12: The researchers provide a balanced view by reporting not only high-level throughput but also memory overheads and specific scenarios where the system underperforms. This transparency regarding performance trade-offs and multi-NUMA bottlenecks indicates a low risk of reporting bias. | AR12: 1 | AS12: 0 | AT12: -1 | AU12: 2 | AV12: 1 | AW12: =sum(AR12:AV12) -> 3 | AX12: =IF(AW12>=8,"Low",IF(AW12>=4,"Moderate",IF(AW12>=0,"Serious","Critical"))) -> Serious | AY12: The use of a clear warm-up period and the focus on minimizing monitoring overhead are strong practices. However, the lack of reported statistical variance (error bars) and specific details on the number of repeated trials introduces some uncertainty regarding the precision of the measurements. | AZ12: 2 | BA12: 2 | BB12: 2 | BC12: 1 | BD12: 2 | BE12: =sum(AZ12:BD12) -> 9 | BF12: =IF(BE12>=8,"Low",IF(BE12>=4,"Moderate",IF(BE12>=0,"Serious","Critical"))) -> Low | BG12: The paper avoids "cherry-picking" by testing against a standard benchmark suite (YCSB) and including diverse real-world datasets of varying difficulty. By highlighting cases where existing models are superior or where DiffLex hits performance ceilings, the authors demonstrate a commitment to objective reporting. | BH12: =SUM(I12,Q12,Y12,AG12,AO12,AW12,BE12) -> 56 | BI12: =IF(BH12>=56,"Low",IF(BH12>=35,"Moderate",IF(BH12>=14,"Serious","Critical"))) -> Low | BJ12: FALSE
A13: 11 | B13: LCKV: Learner-Cleaner Optimized Adaptive Key-Value Separated LSM-Tree Store | C13: 2024 | D13: 2 | E13: 2 | F13: 1 | G13: 2 | H13: 1 | I13: =SUM(D13:H13) -> 8 | J13: =IF(I13>=8,"Low",IF(I13>=4,"Moderate",IF(I13>=0,"Serious","Critical"))) -> Low | K13: The paper provides comprehensive details regarding the hardware environment and software versions, ensuring a controlled testing environment. While specific kernel-level environmental controls are not detailed, the use of standardized KV pair sizes and established baselines supports a fair experimental setup. | L13: 2 | M13: 2 | N13: 0 | O13: 1 | P13: 2 | Q13: =SUM(L13:P13) -> 7 | R13: =IF(Q13>=8,"Low",IF(Q13>=4,"Moderate",IF(Q13>=0,"Serious","Critical"))) -> Moderate | S13: The researchers used a standardized and comprehensive benchmark suite (YCSB) to test a wide array of access patterns. By reporting results across all workloads, including those where LCKV was not the absolute leader, the authors demonstrate a transparent and non-selective evaluation process. | T13: 2 | U13: -1 | V13: 2 | W13: 2 | X13: 2 | Y13: =SUM(T13:X13) -> 7 | Z13: =IF(Y13>=8,"Low",IF(Y13>=4,"Moderate",IF(Y13>=0,"Serious","Critical"))) -> Moderate | AA13: The paper provides a detailed algorithmic and structural breakdown of the LCKV system, specifically regarding the interaction between the Learner and the Cleaner. However, the omission of a public repository link for the LCKV code itself poses a challenge for full independent reproducibility. | AB13: 2 | AC13: 2 | AD13: 0 | AE13: 0 | AF13: 2 | AG13: =SUM(AB13:AF13) -> 6 | AH13: =IF(AG13>=8,"Low",IF(AG13>=4,"Moderate",IF(AG13>=0,"Serious","Critical"))) -> Moderate | AI13: The experimental execution uses standardized, realistic workload patterns (YCSB) and maintains consistency between the proposed Learner-Cleaner architecture and the performance results. However, there is no information regarding thread-level concurrency or system recovery, which are critical for evaluating production-ready storage systems. | AJ13: 1 | AK13: 2 | AL13: 1 | AM13: 2 | AN13: 2 | AO13: =SUM(AJ13:AN13) -> 8 | AP13: =IF(AO13>=8,"Low",IF(AO13>=4,"Moderate",IF(AO13>=0,"Serious","Critical"))) -> Low | AQ13: The paper demonstrates honest reporting by including unfavorable comparisons where LCKV underperforms compared to established baselines. It provides a complete set of results for all promised experiments, although a more explicit section dedicated to the system's limitations would further strengthen the reporting. | AR13: 1 | AS13: 0 | AT13: -2 | AU13: 0 | AV13: 0 | AW13: =sum(AR13:AV13) -> -1 | AX13: =IF(AW13>=8,"Low",IF(AW13>=4,"Moderate",IF(AW13>=0,"Serious","Critical"))) -> Critical | AY13: While the high-level metrics are clearly visualized, there is a significant lack of statistical rigor, specifically the absence of error bars or details regarding repeated trials. Without information on warm-up periods or measurement overhead, it is difficult to determine if the reported throughput is consistently reproducible across different runs. | AZ13: 2 | BA13: 2 | BB13: 2 | BC13: -1 | BD13: 2 | BE13: =sum(AZ13:BD13) -> 7 | BF13: =IF(BE13>=8,"Low",IF(BE13>=4,"Moderate",IF(BE13>=0,"Serious","Critical"))) -> Moderate | BG13: The authors provide a comprehensive and balanced view of LCKV’s performance across all tested scenarios. The primary concern in this domain is reproducibility, as the lack of a public repository for the LCKV implementation hinders independent verification of the results. | BH13: =SUM(I13,Q13,Y13,AG13,AO13,AW13,BE13) -> 42 | BI13: =IF(BH13>=56,"Low",IF(BH13>=35,"Moderate",IF(BH13>=14,"Serious","Critical"))) -> Moderate | BJ13: FALSE
A14: 12 | B14: HIRE: A Hybrid Learned Index for Robust and Efficient Performance under Mixed Workloads | D14: 2 | E14: 2 | F14: 1 | G14: 2 | H14: 2 | I14: =SUM(D14:H14) -> 9 | J14: =IF(I14>=8,"Low",IF(I14>=4,"Moderate",IF(I14>=0,"Serious","Critical"))) -> Low | K14: The study demonstrates a high degree of experimental control by using standardized hardware and compiler settings for all tested indexes. Fairness is maintained by citing the exact GitHub sources for baselines and conducting parameter tuning to ensure each baseline performs at its best. | L14: 2 | M14: 2 | N14: 0 | O14: 0 | P14: 2 | Q14: =SUM(L14:P14) -> 6 | R14: =IF(Q14>=8,"Low",IF(Q14>=4,"Moderate",IF(Q14>=0,"Serious","Critical"))) -> Moderate | S14: The research utilizes established real-world benchmarks (SOSD and GRE) that cover a broad spectrum of data distributions. By including datasets where learned indexes traditionally struggle, the authors provide a robust and non-biased assessment of HIRE’s performance under difficult conditions. | T14: 2 | U14: 1 | V14: 2 | W14: 2 | X14: 2 | Y14: =SUM(T14:X14) -> 9 | Z14: =IF(Y14>=8,"Low",IF(Y14>=4,"Moderate",IF(Y14>=0,"Serious","Critical"))) -> Low | AA14: The implementation details are exceptionally transparent, supported by comprehensive pseudocode and ablation studies that validate the core design choices. The reliance on reputable third-party implementations for all comparisons further reduces the risk of implementation bias. | AB14: 2 | AC14: 2 | AD14: 2 | AE14: 0 | AF14: 2 | AG14: =SUM(AB14:AF14) -> 8 | AH14: =IF(AG14>=8,"Low",IF(AG14>=4,"Moderate",IF(AG14>=0,"Serious","Critical"))) -> Low | AI14: The study executes experiments that are highly consistent with its stated methodology, using standardized workload ratios to test dynamic operations. Concurrency is addressed with specific thread counts and clear synchronization logic, ensuring the execution is both transparent and rigorous. | AJ14: 2 | AK14: 2 | AL14: 2 | AM14: 2 | AN14: 1 | AO14: =SUM(AJ14:AN14) -> 9 | AP14: =IF(AO14>=8,"Low",IF(AO14>=4,"Moderate",IF(AO14>=0,"Serious","Critical"))) -> Low | AQ14: The reporting is exceptionally balanced, as it includes negative findings regarding construction speed and concurrency limits. By acknowledging the limitations of numeric-only indexing and providing ablation data for every core feature, the authors minimize reporting bias. | AR14: 1 | AS14: 1 | AT14: 1 | AU14: 0 | AV14: 1 | AW14: =sum(AR14:AV14) -> 4 | AX14: =IF(AW14>=8,"Low",IF(AW14>=4,"Moderate",IF(AW14>=0,"Serious","Critical"))) -> Moderate | AY14: The use of high-percentile tail latency provides a strong look at performance variance, though the absence of explicit warm-up procedures or timing mechanism details (e.g., specific clock calls) leaves minor room for measurement bias. | AZ14: 2 | BA14: 2 | BB14: 2 | BC14: 1 | BD14: 2 | BE14: =sum(AZ14:BD14) -> 9 | BF14: =IF(BE14>=8,"Low",IF(BE14>=4,"Moderate",IF(BE14>=0,"Serious","Critical"))) -> Low | BG14: The research avoids selective reporting by showcasing diverse performance dimensions, including areas where the proposed method is not the top performer (such as build time). The inclusion of all datasets in the results ensures a complete and honest presentation of the findings. | BH14: =SUM(I14,Q14,Y14,AG14,AO14,AW14,BE14) -> 54 | BI14: =IF(BH14>=56,"Low",IF(BH14>=35,"Moderate",IF(BH14>=14,"Serious","Critical"))) -> Moderate | BJ14: FALSE
A15: 13 | B15: Bounding the Last Mile: Efficient Learned String Indexing | C15: 2021 | D15: 2 | E15: 0 | F15: 0 | G15: 2 | H15: 1 | I15: =SUM(D15:H15) -> 5 | J15: =IF(I15>=8,"Low",IF(I15>=4,"Moderate",IF(I15>=0,"Serious","Critical"))) -> Moderate | K15: The paper excels in selecting and describing relevant real-world datasets and modern baselines. However, it lacks reported detail on the specific hardware and environmental controls used during testing, making it difficult to fully assess experimental confounding. | L15: 2 | M15: 2 | N15: 2 | O15: 1 | P15: 2 | Q15: =SUM(L15:P15) -> 9 | R15: =IF(Q15>=8,"Low",IF(Q15>=4,"Moderate",IF(Q15>=0,"Serious","Critical"))) -> Low | S15: The researchers utilized a robust set of large-scale real-world datasets that represent different string-based challenges. Their willingness to report and analyze poor performance on specific datasets (URLs) demonstrates a lack of selection bias. | T15: 2 | U15: 0 | V15: 2 | W15: 2 | X15: 2 | Y15: =SUM(T15:X15) -> 8 | Z15: =IF(Y15>=8,"Low",IF(Y15>=4,"Moderate",IF(Y15>=0,"Serious","Critical"))) -> Low | AA15: The methodology and architecture of RSS are well-documented, and the use of established baselines ensures the comparison is meaningful. The primary limitation in this domain is the absence of a direct link to the source code in the provided text. | AB15: 2 | AC15: 0 | AD15: 0 | AE15: 0 | AF15: 2 | AG15: =SUM(AB15:AF15) -> 4 | AH15: =IF(AG15>=8,"Low",IF(AG15>=4,"Moderate",IF(AG15>=0,"Serious","Critical"))) -> Moderate | AI15: The experiments are highly consistent with the primary indexing and dictionary encoding scenarios described. However, the evaluation is limited to static datasets, as the authors intentionally exclude dynamic operations and concurrency from the scope of this work. | AJ15: 2 | AK15: 2 | AL15: 2 | AM15: 2 | AN15: 2 | AO15: =SUM(AJ15:AN15) -> 10 | AP15: =IF(AO15>=8,"Low",IF(AO15>=4,"Moderate",IF(AO15>=0,"Serious","Critical"))) -> Low | AQ15: The reporting is comprehensive and transparent. The authors do not hide the fact that their method can be slower than competitors like HOT on certain datasets and provide a technical explanation for these performance characteristics. | AR15: 0 | AS15: 0 | AT15: -2 | AU15: 0 | AV15: 0 | AW15: =sum(AR15:AV15) -> -2 | AX15: =IF(AW15>=8,"Low",IF(AW15>=4,"Moderate",IF(AW15>=0,"Serious","Critical"))) -> Critical | AY15: While the metrics reported are standard, the lack of information regarding measurement rigor—such as statistical variance, hardware environment, and timing mechanisms—introduces uncertainty regarding the precision and replicability of the performance numbers. | AZ15: 2 | BA15: 2 | BB15: 2 | BC15: 1 | BD15: 2 | BE15: =sum(AZ15:BD15) -> 9 | BF15: =IF(BE15>=8,"Low",IF(BE15>=4,"Moderate",IF(BE15>=0,"Serious","Critical"))) -> Low | BG15: The paper demonstrates a balanced selection of results, including data where the proposed method is not the top performer. Transparency is high regarding the datasets used, though the accessibility of the exact source code for RSS is not explicitly confirmed in the text | BH15: =SUM(I15,Q15,Y15,AG15,AO15,AW15,BE15) -> 43 | BI15: =IF(BH15>=56,"Low",IF(BH15>=35,"Moderate",IF(BH15>=14,"Serious","Critical"))) -> Moderate | BJ15: FALSE
A16: 14 | B16: BLI: A High-performance Bucket-based Learned Index with Concurrency Support | C16: 2025 | D16: 2 | E16: 2 | F16: 1 | G16: 2 | H16: 1 | I16: =SUM(D16:H16) -> 8 | J16: =IF(I16>=8,"Low",IF(I16>=4,"Moderate",IF(I16>=0,"Serious","Critical"))) -> Low | K16: The research demonstrates strong experimental control by detailing hardware specifications and utilizing a recognized third-party benchmarking suite for baseline implementations. While specific system-level controls like cache flushing are not explicitly documented, the thorough description of dataset "hardness" and key sizes ensures a transparent comparison environment. | L16: 2 | M16: 2 | N16: 0 | O16: 2 | P16: 1 | Q16: =SUM(L16:P16) -> 7 | R16: =IF(Q16>=8,"Low",IF(Q16>=4,"Moderate",IF(Q16>=0,"Serious","Critical"))) -> Moderate | S16: Dataset selection is well-justified and follows established research precedents by categorizing data based on distribution complexity. The inclusion of negative results regarding range query performance and specific dataset scenarios provides significant evidence against cherry-picking and suggests a balanced evaluation. | T16: 2 | U16: 2 | V16: 2 | W16: 2 | X16: 2 | Y16: =SUM(T16:X16) -> 10 | Z16: =IF(Y16>=8,"Low",IF(Y16>=4,"Moderate",IF(Y16>=0,"Serious","Critical"))) -> Low | AA16: The implementation is highly transparent, featuring detailed pseudocode for its core logic and providing public access to the source code for reproducibility. By using baseline implementations from an established benchmarking paper, the study avoids "strawman" comparisons and ensures all tested systems are properly optimized. | AB16: 2 | AC16: 2 | AD16: 2 | AE16: 0 | AF16: 2 | AG16: =SUM(AB16:AF16) -> 8 | AH16: =IF(AG16>=8,"Low",IF(AG16>=4,"Moderate",IF(AG16>=0,"Serious","Critical"))) -> Low | AI16: The experiments are executed with well-defined workload parameters and cover a diverse range of operational ratios, which accurately reflect the needs of dynamic learned indexes. While the paper lacks information on crash recovery, it provides a thorough evaluation of concurrency using realistic thread counts and detailed synchronization mechanisms. | AJ16: 2 | AK16: 2 | AL16: 2 | AM16: 2 | AN16: 2 | AO16: =SUM(AJ16:AN16) -> 10 | AP16: =IF(AO16>=8,"Low",IF(AO16>=4,"Moderate",IF(AO16>=0,"Serious","Critical"))) -> Low | AQ16: The researchers provide a highly transparent report that includes comprehensive performance dimensions and explicitly highlights where their system is weaker than existing state-of-the-art methods. By explaining anomalies in performance and acknowledging design trade-offs, they minimize the risk of reporting bias. | AR16: 1 | AS16: 0 | AT16: -1 | AU16: 0 | AV16: 0 | AW16: =sum(AR16:AV16) -> 0 | AX16: =IF(AW16>=8,"Low",IF(AW16>=4,"Moderate",IF(AW16>=0,"Serious","Critical"))) -> Serious | AY16: While the metrics and benchmarks used are standard for the field, there is a lack of statistical detail regarding measurement variance and experimental repetition. The absence of error bars and explicit warm-up procedures suggests some risk that transient system effects could influence the reported numbers. | AZ16: 2 | BA16: 2 | BB16: 2 | BC16: 2 | BD16: 2 | BE16: =sum(AZ16:BD16) -> 10 | BF16: =IF(BE16>=8,"Low",IF(BE16>=4,"Moderate",IF(BE16>=0,"Serious","Critical"))) -> Low | BG16: The research displays high integrity in result selection by providing public access to source code and artifacts for verification. The inclusion of comprehensive workload ratios and the explicit reporting of unfavorable performance results in specific scenarios strongly suggests the absence of selective reporting or cherry-picking. | BH16: =SUM(I16,Q16,Y16,AG16,AO16,AW16,BE16) -> 53 | BI16: =IF(BH16>=56,"Low",IF(BH16>=35,"Moderate",IF(BH16>=14,"Serious","Critical"))) -> Moderate | BJ16: FALSE
A17: 15 | B17: The PGM-index: a fully-dynamic compressed learned index with provable worst-case bounds | C17: 2020 | D17: 2 | E17: 1 | F17: 1 | G17: 2 | H17: 2 | I17: =SUM(D17:H17) -> 8 | J17: =IF(I17>=8,"Low",IF(I17>=4,"Moderate",IF(I17>=0,"Serious","Critical"))) -> Low | K17: The paper demonstrates strong experimental control by using widely recognized baseline libraries and ensuring the competitor structures are optimized through various configurations like page sizes and model counts. While some environment-specific details like OS versions are missing, the use of randomized operation batches to control for hardware prefetching shows a high level of concern for experimental fairness. | L17: 1 | M17: 2 | N17: 0 | O17: 2 | P17: 2 | Q17: =SUM(L17:P17) -> 7 | R17: =IF(Q17>=8,"Low",IF(Q17>=4,"Moderate",IF(Q17>=0,"Serious","Critical"))) -> Moderate | S17: The dataset selection is robust, covering a wide range of synthetic statistical distributions and standard real-world benchmarks that vary in size and pattern. The authors avoid cherry-picking by reporting comprehensive results across various error tolerances (ϵ) and identifying specific scenarios where their secondary optimizations, like slope compression, do not perform well. | T17: 2 | U17: 2 | V17: 2 | W17: 2 | X17: 2 | Y17: =SUM(T17:X17) -> 10 | Z17: =IF(Y17>=8,"Low",IF(Y17>=4,"Moderate",IF(Y17>=0,"Serious","Critical"))) -> Low | AA17: The paper excels in implementation transparency by providing both rigorous theoretical proofs and clear pseudocode for its algorithms. By releasing the source code and utilizing highly optimized, reputable libraries for baseline comparisons, the authors minimize the risk of "strawman" benchmarking or implementation bias. | AB17: 2 | AC17: 2 | AD17: 0 | AE17: 0 | AF17: 2 | AG17: =SUM(AB17:AF17) -> 6 | AH17: =IF(AG17>=8,"Low",IF(AG17>=4,"Moderate",IF(AG17>=0,"Serious","Critical"))) -> Moderate | AI17: The experimental execution is robust regarding workload definitions and the handling of dynamic operations, specifically avoiding hardware-level shortcuts like speculative execution. However, because the paper's scope is primarily on the algorithmic design of the index structure itself, details on concurrency and crash recovery are absent from the sources. | AJ17: 2 | AK17: 2 | AL17: 2 | AM17: 2 | AN17: 2 | AO17: =SUM(AJ17:AN17) -> 10 | AP17: =IF(AO17>=8,"Low",IF(AO17>=4,"Moderate",IF(AO17>=0,"Serious","Critical"))) -> Low | AQ17: The paper is transparent about the performance trade-offs, showing exactly when and why the PGM-index might underperform traditional structures. The reporting is comprehensive, covering all promised configurations and acknowledging the complexity of dynamic updates. | AR17: 1 | AS17: 1 | AT17: 2 | AU17: 0 | AV17: 0 | AW17: =sum(AR17:AV17) -> 4 | AX17: =IF(AW17>=8,"Low",IF(AW17>=4,"Moderate",IF(AW17>=0,"Serious","Critical"))) -> Moderate | AY17: The paper uses rigorous batch testing and reports statistical variance for its error-approximation models. However, it lacks specific details regarding low-level measurement overheads and explicit warm-up procedures, which are common in high-performance computing benchmarks. | AZ17: 2 | BA17: 2 | BB17: 2 | BC17: 2 | BD17: 2 | BE17: =sum(AZ17:BD17) -> 10 | BF17: =IF(BE17>=8,"Low",IF(BE17>=4,"Moderate",IF(BE17>=0,"Serious","Critical"))) -> Low | BG17: The authors demonstrate high integrity by reporting a wide range of outcomes, including where the B+-tree is superior and where compression adds latency. The public availability of their source code further supports the lack of selective reporting bias. | BH17: =SUM(I17,Q17,Y17,AG17,AO17,AW17,BE17) -> 55 | BI17: =IF(BH17>=56,"Low",IF(BH17>=35,"Moderate",IF(BH17>=14,"Serious","Critical"))) -> Moderate | BJ17: FALSE
